Workbook

Sheet experiment_data
A1: user_id | B1: signup_date | C1: experiment_group | D1: region | E1: device_type | F1: traffic_source | G1: plan_type | H1: visited_landing_page | I1: started_trial | J1: completed_onboarding | K1: converted_to_paid | L1: revenue_30d | M1: support_tickets_30d | N1: refund_requested | O1: days_to_convert | P1: engagement_score | Q1: duplicate_check | R1: Landing Validation | S1: Trial Validation | T1: Onboarding Validation | U1: Conversion Validation | V1: Refund Validation | W1: revenue_outlier_check
A2: USR-100001 | B2: 45732 | C2: Control | D2: North | E2: Desktop | F2: Email | G2: Basic | H2: 0 | I2: 0 | J2: 0 | K2: 0 | L2: 0 | M2: 0 | N2: 0 | P2: 45.7 | Q2: =IF(COUNTIF($A$2:A2,A2)>1,"Duplicate","Unique") -> Unique | R2: =IF(OR(H2=0,H2=1),"Valid","Invalid") -> Valid | S2: =IF(OR(I2=0,I2=1),"Valid","Invalid") -> Valid | T2: =IF(OR(J2=0,J2=1),"Valid","Invalid") -> Valid | U2: =IF(OR(K2=0,K2=1),"Valid","Invalid") -> Valid | V2: =IF(OR(N2=0,N2=1),"Valid","Invalid") -> Valid | W2: =IF(OR(L2<$B$23,L2>$B$24),"Outlier","Normal") -> Outlier
A3: USR-100002 | B3: 45724 | C3: Control | D3: West | E3: Mobile | F3: Organic | G3: Free | H3: 1 | I3: 0 | J3: 0 | K3: 0 | L3: 0 | M3: 0 | N3: 0 | P3: 48.6 | Q3: =IF(COUNTIF($A$2:A3,A3)>1,"Duplicate","Unique") -> Unique | R3: =IF(OR(H3=0,H3=1),"Valid","Invalid") -> Valid | S3: =IF(OR(I3=0,I3=1),"Valid","Invalid") -> Valid | T3: =IF(OR(J3=0,J3=1),"Valid","Invalid") -> Valid | U3: =IF(OR(K3=0,K3=1),"Valid","Invalid") -> Valid | V3: =IF(OR(N3=0,N3=1),"Valid","Invalid") -> Valid | W3: =IF(OR(L3<$B$23,L3>$B$24),"Outlier","Normal") -> Outlier
A4: USR-100003 | B4: 45771 | C4: Control | D4: East | E4: Mobile | F4: Paid Search | G4: Premium | H4: 1 | I4: 0 | J4: 0 | K4: 0 | L4: 0 | M4: 1 | N4: 0 | P4: 35.4 | Q4: =IF(COUNTIF($A$2:A4,A4)>1,"Duplicate","Unique") -> Unique | R4: =IF(OR(H4=0,H4=1),"Valid","Invalid") -> Valid | S4: =IF(OR(I4=0,I4=1),"Valid","Invalid") -> Valid | T4: =IF(OR(J4=0,J4=1),"Valid","Invalid") -> Valid | U4: =IF(OR(K4=0,K4=1),"Valid","Invalid") -> Valid | V4: =IF(OR(N4=0,N4=1),"Valid","Invalid") -> Valid | W4: =IF(OR(L4<$B$23,L4>$B$24),"Outlier","Normal") -> Outlier
A5: USR-100004 | B5: 45781 | C5: Control | D5: South | E5: Mobile | F5: Email | G5: Basic | H5: 1 | I5: 0 | J5: 0 | K5: 0 | L5: 0 | M5: 0 | N5: 0 | P5: 64.6 | Q5: =IF(COUNTIF($A$2:A5,A5)>1,"Duplicate","Unique") -> Unique | R5: =IF(OR(H5=0,H5=1),"Valid","Invalid") -> Valid | S5: =IF(OR(I5=0,I5=1),"Valid","Invalid") -> Valid | T5: =IF(OR(J5=0,J5=1),"Valid","Invalid") -> Valid | U5: =IF(OR(K5=0,K5=1),"Valid","Invalid") -> Valid | V5: =IF(OR(N5=0,N5=1),"Valid","Invalid") -> Valid | W5: =IF(OR(L5<$B$23,L5>$B$24),"Outlier","Normal") -> Outlier
A6: USR-100005 | B6: 45700 | C6: Control | D6: North | E6: Tablet | F6: Organic | G6: Free | H6: 0 | I6: 0 | J6: 0 | K6: 0 | L6: 0 | M6: 0 | N6: 0 | P6: 66.6 | Q6: =IF(COUNTIF($A$2:A6,A6)>1,"Duplicate","Unique") -> Unique | R6: =IF(OR(H6=0,H6=1),"Valid","Invalid") -> Valid | S6: =IF(OR(I6=0,I6=1),"Valid","Invalid") -> Valid | T6: =IF(OR(J6=0,J6=1),"Valid","Invalid") -> Valid | U6: =IF(OR(K6=0,K6=1),"Valid","Invalid") -> Valid | V6: =IF(OR(N6=0,N6=1),"Valid","Invalid") -> Valid | W6: =IF(OR(L6<$B$23,L6>$B$24),"Outlier","Normal") -> Outlier
A7: USR-100006 | B7: 45685 | C7: Control | D7: East | E7: Mobile | F7: Organic | G7: Premium | H7: 1 | I7: 0 | J7: 0 | K7: 0 | L7: 0 | M7: 0 | N7: 0 | P7: 40.8 | Q7: =IF(COUNTIF($A$2:A7,A7)>1,"Duplicate","Unique") -> Unique | R7: =IF(OR(H7=0,H7=1),"Valid","Invalid") -> Valid | S7: =IF(OR(I7=0,I7=1),"Valid","Invalid") -> Valid | T7: =IF(OR(J7=0,J7=1),"Valid","Invalid") -> Valid | U7: =IF(OR(K7=0,K7=1),"Valid","Invalid") -> Valid | V7: =IF(OR(N7=0,N7=1),"Valid","Invalid") -> Valid | W7: =IF(OR(L7<$B$23,L7>$B$24),"Outlier","Normal") -> Outlier
A8: USR-100007 | B8: 45755 | C8: Control | D8: East | E8: Mobile | F8: Paid Search | G8: Basic | H8: 1 | I8: 1 | J8: 0 | K8: 0 | L8: 0 | M8: 0 | N8: 0 | P8: 57.1 | Q8: =IF(COUNTIF($A$2:A8,A8)>1,"Duplicate","Unique") -> Unique | R8: =IF(OR(H8=0,H8=1),"Valid","Invalid") -> Valid | S8: =IF(OR(I8=0,I8=1),"Valid","Invalid") -> Valid | T8: =IF(OR(J8=0,J8=1),"Valid","Invalid") -> Valid | U8: =IF(OR(K8=0,K8=1),"Valid","Invalid") -> Valid | V8: =IF(OR(N8=0,N8=1),"Valid","Invalid") -> Valid | W8: =IF(OR(L8<$B$23,L8>$B$24),"Outlier","Normal") -> Outlier
A9: USR-100008 | B9: 45794 | C9: Control | D9: South | E9: Mobile | F9: Paid Search | G9: Free | H9: 0 | I9: 0 | J9: 0 | K9: 0 | L9: 0 | M9: 0 | N9: 0 | P9: 36.4 | Q9: =IF(COUNTIF($A$2:A9,A9)>1,"Duplicate","Unique") -> Unique | R9: =IF(OR(H9=0,H9=1),"Valid","Invalid") -> Valid | S9: =IF(OR(I9=0,I9=1),"Valid","Invalid") -> Valid | T9: =IF(OR(J9=0,J9=1),"Valid","Invalid") -> Valid | U9: =IF(OR(K9=0,K9=1),"Valid","Invalid") -> Valid | V9: =IF(OR(N9=0,N9=1),"Valid","Invalid") -> Valid | W9: =IF(OR(L9<$B$23,L9>$B$24),"Outlier","Normal") -> Outlier
A10: USR-100009 | B10: 45711 | C10: Control | D10: South | E10: Tablet | F10: Referral | G10: Basic | H10: 0 | I10: 0 | J10: 0 | K10: 0 | L10: 0 | M10: 0 | N10: 0 | P10: 55.4 | Q10: =IF(COUNTIF($A$2:A10,A10)>1,"Duplicate","Unique") -> Unique | R10: =IF(OR(H10=0,H10=1),"Valid","Invalid") -> Valid | S10: =IF(OR(I10=0,I10=1),"Valid","Invalid") -> Valid | T10: =IF(OR(J10=0,J10=1),"Valid","Invalid") -> Valid | U10: =IF(OR(K10=0,K10=1),"Valid","Invalid") -> Valid | V10: =IF(OR(N10=0,N10=1),"Valid","Invalid") -> Valid | W10: =IF(OR(L10<$B$23,L10>$B$24),"Outlier","Normal") -> Outlier
A11: USR-100010 | B11: 45806 | C11: Control | D11: West | E11: Desktop | F11: Social | G11: Free | H11: 1 | I11: 0 | J11: 0 | K11: 0 | L11: 0 | M11: 0 | N11: 0 | P11: 57.3 | Q11: =IF(COUNTIF($A$2:A11,A11)>1,"Duplicate","Unique") -> Unique | R11: =IF(OR(H11=0,H11=1),"Valid","Invalid") -> Valid | S11: =IF(OR(I11=0,I11=1),"Valid","Invalid") -> Valid | T11: =IF(OR(J11=0,J11=1),"Valid","Invalid") -> Valid | U11: =IF(OR(K11=0,K11=1),"Valid","Invalid") -> Valid | V11: =IF(OR(N11=0,N11=1),"Valid","Invalid") -> Valid | W11: =IF(OR(L11<$B$23,L11>$B$24),"Outlier","Normal") -> Outlier
A12: USR-100011 | B12: 45777 | C12: Control | D12: East | E12: Mobile | F12: Paid Search | G12: Basic | H12: 1 | I12: 1 | J12: 1 | K12: 0 | L12: 0 | M12: 0 | N12: 0 | P12: 63.6 | Q12: =IF(COUNTIF($A$2:A12,A12)>1,"Duplicate","Unique") -> Unique | R12: =IF(OR(H12=0,H12=1),"Valid","Invalid") -> Valid | S12: =IF(OR(I12=0,I12=1),"Valid","Invalid") -> Valid | T12: =IF(OR(J12=0,J12=1),"Valid","Invalid") -> Valid | U12: =IF(OR(K12=0,K12=1),"Valid","Invalid") -> Valid | V12: =IF(OR(N12=0,N12=1),"Valid","Invalid") -> Valid | W12: =IF(OR(L12<$B$23,L12>$B$24),"Outlier","Normal") -> Outlier
A13: USR-100012 | B13: 45732 | C13: Control | D13: East | E13: Mobile | F13: Social | G13: Premium | H13: 1 | I13: 1 | J13: 1 | K13: 0 | L13: 0 | M13: 1 | N13: 0 | P13: 80.4 | Q13: =IF(COUNTIF($A$2:A13,A13)>1,"Duplicate","Unique") -> Unique | R13: =IF(OR(H13=0,H13=1),"Valid","Invalid") -> Valid | S13: =IF(OR(I13=0,I13=1),"Valid","Invalid") -> Valid | T13: =IF(OR(J13=0,J13=1),"Valid","Invalid") -> Valid | U13: =IF(OR(K13=0,K13=1),"Valid","Invalid") -> Valid | V13: =IF(OR(N13=0,N13=1),"Valid","Invalid") -> Valid | W13: =IF(OR(L13<$B$23,L13>$B$24),"Outlier","Normal") -> Outlier
... A60: USR-100059 | B60: 45761 | C60: Control | D60: North | E60: Mobile | F60: Social | G60: Free | H60: 0 | I60: 0 | J60: 0 | K60: 0 | L60: 0 | M60: 2 | N60: 0 | P60: 48.9 | Q60: =IF(COUNTIF($A$2:A60,A60)>1,"Duplicate","Unique") -> Unique | R60: =IF(OR(H60=0,H60=1),"Valid","Invalid") -> Valid | S60: =IF(OR(I60=0,I60=1),"Valid","Invalid") -> Valid | T60: =IF(OR(J60=0,J60=1),"Valid","Invalid") -> Valid | U60: =IF(OR(K60=0,K60=1),"Valid","Invalid") -> Valid | V60: =IF(OR(N60=0,N60=1),"Valid","Invalid") -> Valid | W60: =IF(OR(L60<$B$23,L60>$B$24),"Outlier","Normal") -> Outlier
A61: USR-100060 | B61: 45658 | C61: Control | D61: West | E61: Mobile | F61: Social | G61: Free | H61: 1 | I61: 1 | J61: 1 | K61: 1 | L61: 240.42 | M61: 0 | N61: 0 | O61: 16 | P61: 56.5 | Q61: =IF(COUNTIF($A$2:A61,A61)>1,"Duplicate","Unique") -> Unique | R61: =IF(OR(H61=0,H61=1),"Valid","Invalid") -> Valid | S61: =IF(OR(I61=0,I61=1),"Valid","Invalid") -> Valid | T61: =IF(OR(J61=0,J61=1),"Valid","Invalid") -> Valid | U61: =IF(OR(K61=0,K61=1),"Valid","Invalid") -> Valid | V61: =IF(OR(N61=0,N61=1),"Valid","Invalid") -> Valid | W61: =IF(OR(L61<$B$23,L61>$B$24),"Outlier","Normal") -> Outlier
A62: USR-100061 | B62: 45749 | C62: Control | D62: South | E62: Mobile | F62: Referral | G62: Free | H62: 1 | I62: 0 | J62: 0 | K62: 0 | L62: 0 | M62: 0 | N62: 0 | P62: 53.7 | Q62: =IF(COUNTIF($A$2:A62,A62)>1,"Duplicate","Unique") -> Unique | R62: =IF(OR(H62=0,H62=1),"Valid","Invalid") -> Valid | S62: =IF(OR(I62=0,I62=1),"Valid","Invalid") -> Valid | T62: =IF(OR(J62=0,J62=1),"Valid","Invalid") -> Valid | U62: =IF(OR(K62=0,K62=1),"Valid","Invalid") -> Valid | V62: =IF(OR(N62=0,N62=1),"Valid","Invalid") -> Valid | W62: =IF(OR(L62<$B$23,L62>$B$24),"Outlier","Normal") -> Outlier
A63: USR-100062 | B63: 45745 | C63: Control | D63: North | E63: Mobile | F63: Social | G63: Premium | H63: 0 | I63: 0 | J63: 0 | K63: 0 | L63: 0 | M63: 0 | N63: 0 | P63: 62.2 | Q63: =IF(COUNTIF($A$2:A63,A63)>1,"Duplicate","Unique") -> Unique | R63: =IF(OR(H63=0,H63=1),"Valid","Invalid") -> Valid | S63: =IF(OR(I63=0,I63=1),"Valid","Invalid") -> Valid | T63: =IF(OR(J63=0,J63=1),"Valid","Invalid") -> Valid | U63: =IF(OR(K63=0,K63=1),"Valid","Invalid") -> Valid | V63: =IF(OR(N63=0,N63=1),"Valid","Invalid") -> Valid | W63: =IF(OR(L63<$B$23,L63>$B$24),"Outlier","Normal") -> Outlier
A64: USR-100063 | B64: 45792 | C64: Control | D64: South | E64: Desktop | F64: Organic | G64: Free | H64: 1 | I64: 0 | J64: 0 | K64: 0 | L64: 0 | M64: 0 | N64: 0 | P64: 50.2 | Q64: =IF(COUNTIF($A$2:A64,A64)>1,"Duplicate","Unique") -> Unique | R64: =IF(OR(H64=0,H64=1),"Valid","Invalid") -> Valid | S64: =IF(OR(I64=0,I64=1),"Valid","Invalid") -> Valid | T64: =IF(OR(J64=0,J64=1),"Valid","Invalid") -> Valid | U64: =IF(OR(K64=0,K64=1),"Valid","Invalid") -> Valid | V64: =IF(OR(N64=0,N64=1),"Valid","Invalid") -> Valid | W64: =IF(OR(L64<$B$23,L64>$B$24),"Outlier","Normal") -> Outlier
A65: USR-100064 | B65: 45758 | C65: Control | D65: North | E65: Mobile | F65: Organic | G65: Basic | H65: 1 | I65: 0 | J65: 0 | K65: 0 | L65: 0 | M65: 0 | N65: 0 | P65: 74.3 | Q65: =IF(COUNTIF($A$2:A65,A65)>1,"Duplicate","Unique") -> Unique | R65: =IF(OR(H65=0,H65=1),"Valid","Invalid") -> Valid | S65: =IF(OR(I65=0,I65=1),"Valid","Invalid") -> Valid | T65: =IF(OR(J65=0,J65=1),"Valid","Invalid") -> Valid | U65: =IF(OR(K65=0,K65=1),"Valid","Invalid") -> Valid | V65: =IF(OR(N65=0,N65=1),"Valid","Invalid") -> Valid | W65: =IF(OR(L65<$B$23,L65>$B$24),"Outlier","Normal") -> Outlier
A66: USR-100065 | B66: 45723 | C66: Control | D66: South | E66: Desktop | F66: Paid Search | G66: Free | H66: 1 | I66: 0 | J66: 0 | K66: 0 | L66: 0 | M66: 0 | N66: 0 | P66: 58 | Q66: =IF(COUNTIF($A$2:A66,A66)>1,"Duplicate","Unique") -> Unique | R66: =IF(OR(H66=0,H66=1),"Valid","Invalid") -> Valid | S66: =IF(OR(I66=0,I66=1),"Valid","Invalid") -> Valid | T66: =IF(OR(J66=0,J66=1),"Valid","Invalid") -> Valid | U66: =IF(OR(K66=0,K66=1),"Valid","Invalid") -> Valid | V66: =IF(OR(N66=0,N66=1),"Valid","Invalid") -> Valid | W66: =IF(OR(L66<$B$23,L66>$B$24),"Outlier","Normal") -> Outlier
A67: USR-100066 | B67: 45807 | C67: Control | D67: South | E67: Mobile | F67: Organic | G67: Free | H67: 0 | I67: 0 | J67: 0 | K67: 0 | L67: 0 | M67: 0 | N67: 0 | P67: 46.7 | Q67: =IF(COUNTIF($A$2:A67,A67)>1,"Duplicate","Unique") -> Unique | R67: =IF(OR(H67=0,H67=1),"Valid","Invalid") -> Valid | S67: =IF(OR(I67=0,I67=1),"Valid","Invalid") -> Valid | T67: =IF(OR(J67=0,J67=1),"Valid","Invalid") -> Valid | U67: =IF(OR(K67=0,K67=1),"Valid","Invalid") -> Valid | V67: =IF(OR(N67=0,N67=1),"Valid","Invalid") -> Valid | W67: =IF(OR(L67<$B$23,L67>$B$24),"Outlier","Normal") -> Outlier
A68: USR-100067 | B68: 45664 | C68: Control | D68: South | E68: Desktop | F68: Organic | G68: Premium | H68: 1 | I68: 0 | J68: 0 | K68: 0 | L68: 0 | M68: 1 | N68: 0 | P68: 49.6 | Q68: =IF(COUNTIF($A$2:A68,A68)>1,"Duplicate","Unique") -> Unique | R68: =IF(OR(H68=0,H68=1),"Valid","Invalid") -> Valid | S68: =IF(OR(I68=0,I68=1),"Valid","Invalid") -> Valid | T68: =IF(OR(J68=0,J68=1),"Valid","Invalid") -> Valid | U68: =IF(OR(K68=0,K68=1),"Valid","Invalid") -> Valid | V68: =IF(OR(N68=0,N68=1),"Valid","Invalid") -> Valid | W68: =IF(OR(L68<$B$23,L68>$B$24),"Outlier","Normal") -> Outlier
A69: USR-100068 | B69: 45785 | C69: Control | D69: West | E69: Mobile | F69: Social | G69: Free | H69: 0 | I69: 0 | J69: 0 | K69: 0 | L69: 0 | M69: 0 | N69: 0 | P69: 60.4 | Q69: =IF(COUNTIF($A$2:A69,A69)>1,"Duplicate","Unique") -> Unique | R69: =IF(OR(H69=0,H69=1),"Valid","Invalid") -> Valid | S69: =IF(OR(I69=0,I69=1),"Valid","Invalid") -> Valid | T69: =IF(OR(J69=0,J69=1),"Valid","Invalid") -> Valid | U69: =IF(OR(K69=0,K69=1),"Valid","Invalid") -> Valid | V69: =IF(OR(N69=0,N69=1),"Valid","Invalid") -> Valid | W69: =IF(OR(L69<$B$23,L69>$B$24),"Outlier","Normal") -> Outlier
A70: USR-100069 | B70: 45735 | C70: Control | D70: East | E70: Desktop | F70: Email | G70: Free | H70: 1 | I70: 1 | J70: 1 | K70: 0 | L70: 0 | M70: 0 | N70: 0 | P70: 55.3 | Q70: =IF(COUNTIF($A$2:A70,A70)>1,"Duplicate","Unique") -> Unique | R70: =IF(OR(H70=0,H70=1),"Valid","Invalid") -> Valid | S70: =IF(OR(I70=0,I70=1),"Valid","Invalid") -> Valid | T70: =IF(OR(J70=0,J70=1),"Valid","Invalid") -> Valid | U70: =IF(OR(K70=0,K70=1),"Valid","Invalid") -> Valid | V70: =IF(OR(N70=0,N70=1),"Valid","Invalid") -> Valid | W70: =IF(OR(L70<$B$23,L70>$B$24),"Outlier","Normal") -> Outlier
A71: USR-100070 | B71: 45793 | C71: Control | D71: North | E71: Desktop | F71: Organic | G71: Free | H71: 0 | I71: 0 | J71: 0 | K71: 0 | L71: 0 | M71: 0 | N71: 0 | P71: 56.2 | Q71: =IF(COUNTIF($A$2:A71,A71)>1,"Duplicate","Unique") -> Unique | R71: =IF(OR(H71=0,H71=1),"Valid","Invalid") -> Valid | S71: =IF(OR(I71=0,I71=1),"Valid","Invalid") -> Valid | T71: =IF(OR(J71=0,J71=1),"Valid","Invalid") -> Valid | U71: =IF(OR(K71=0,K71=1),"Valid","Invalid") -> Valid | V71: =IF(OR(N71=0,N71=1),"Valid","Invalid") -> Valid | W71: =IF(OR(L71<$B$23,L71>$B$24),"Outlier","Normal") -> Outlier
A72: USR-100071 | B72: 45724 | C72: Control | D72: West | E72: Mobile | F72: Email | G72: Free | H72: 0 | I72: 0 | J72: 0 | K72: 0 | L72: 0 | M72: 0 | N72: 0 | P72: 29.4 | Q72: =IF(COUNTIF($A$2:A72,A72)>1,"Duplicate","Unique") -> Unique | R72: =IF(OR(H72=0,H72=1),"Valid","Invalid") -> Valid | S72: =IF(OR(I72=0,I72=1),"Valid","Invalid") -> Valid | T72: =IF(OR(J72=0,J72=1),"Valid","Invalid") -> Valid | U72: =IF(OR(K72=0,K72=1),"Valid","Invalid") -> Valid | V72: =IF(OR(N72=0,N72=1),"Valid","Invalid") -> Valid | W72: =IF(OR(L72<$B$23,L72>$B$24),"Outlier","Normal") -> Outlier
A73: USR-100072 | B73: 45724 | C73: Control | D73: East | E73: Mobile | F73: Email | G73: Free | H73: 1 | I73: 0 | J73: 0 | K73: 0 | L73: 0 | M73: 0 | N73: 0 | P73: 54.2 | Q73: =IF(COUNTIF($A$2:A73,A73)>1,"Duplicate","Unique") -> Unique | R73: =IF(OR(H73=0,H73=1),"Valid","Invalid") -> Valid | S73: =IF(OR(I73=0,I73=1),"Valid","Invalid") -> Valid | T73: =IF(OR(J73=0,J73=1),"Valid","Invalid") -> Valid | U73: =IF(OR(K73=0,K73=1),"Valid","Invalid") -> Valid | V73: =IF(OR(N73=0,N73=1),"Valid","Invalid") -> Valid | W73: =IF(OR(L73<$B$23,L73>$B$24),"Outlier","Normal") -> Outlier
... A79: USR-100078 | B79: 45673 | C79: Control | D79: North | E79: Mobile | F79: Organic | G79: Free | H79: 0 | I79: 0 | J79: 0 | K79: 0 | L79: 0 | M79: 2 | N79: 0 | P79: 48.4 | Q79: =IF(COUNTIF($A$2:A79,A79)>1,"Duplicate","Unique") -> Unique | R79: =IF(OR(H79=0,H79=1),"Valid","Invalid") -> Valid | S79: =IF(OR(I79=0,I79=1),"Valid","Invalid") -> Valid | T79: =IF(OR(J79=0,J79=1),"Valid","Invalid") -> Valid | U79: =IF(OR(K79=0,K79=1),"Valid","Invalid") -> Valid | V79: =IF(OR(N79=0,N79=1),"Valid","Invalid") -> Valid | W79: =IF(OR(L79<$B$23,L79>$B$24),"Outlier","Normal") -> Outlier
A80: USR-100079 | B80: 45708 | C80: Control | D80: West | E80: Desktop | F80: Organic | G80: Free | H80: 1 | I80: 1 | J80: 1 | K80: 1 | L80: 457.51 | M80: 0 | N80: 0 | O80: 7 | P80: 38 | Q80: =IF(COUNTIF($A$2:A80,A80)>1,"Duplicate","Unique") -> Unique | R80: =IF(OR(H80=0,H80=1),"Valid","Invalid") -> Valid | S80: =IF(OR(I80=0,I80=1),"Valid","Invalid") -> Valid | T80: =IF(OR(J80=0,J80=1),"Valid","Invalid") -> Valid | U80: =IF(OR(K80=0,K80=1),"Valid","Invalid") -> Valid | V80: =IF(OR(N80=0,N80=1),"Valid","Invalid") -> Valid | W80: =IF(OR(L80<$B$23,L80>$B$24),"Outlier","Normal") -> Outlier
A81: USR-100080 | B81: 45798 | C81: Control | D81: East | E81: Mobile | F81: Social | G81: Free | H81: 1 | I81: 0 | J81: 0 | K81: 0 | L81: 0 | M81: 0 | N81: 0 | P81: 44.2 | Q81: =IF(COUNTIF($A$2:A81,A81)>1,"Duplicate","Unique") -> Unique | R81: =IF(OR(H81=0,H81=1),"Valid","Invalid") -> Valid | S81: =IF(OR(I81=0,I81=1),"Valid","Invalid") -> Valid | T81: =IF(OR(J81=0,J81=1),"Valid","Invalid") -> Valid | U81: =IF(OR(K81=0,K81=1),"Valid","Invalid") -> Valid | V81: =IF(OR(N81=0,N81=1),"Valid","Invalid") -> Valid | W81: =IF(OR(L81<$B$23,L81>$B$24),"Outlier","Normal") -> Outlier
A82: USR-100081 | B82: 45785 | C82: Control | D82: South | E82: Mobile | F82: Organic | G82: Free | H82: 1 | I82: 1 | J82: 1 | K82: 0 | L82: 0 | M82: 0 | N82: 0 | P82: 81.2 | Q82: =IF(COUNTIF($A$2:A82,A82)>1,"Duplicate","Unique") -> Unique | R82: =IF(OR(H82=0,H82=1),"Valid","Invalid") -> Valid | S82: =IF(OR(I82=0,I82=1),"Valid","Invalid") -> Valid | T82: =IF(OR(J82=0,J82=1),"Valid","Invalid") -> Valid | U82: =IF(OR(K82=0,K82=1),"Valid","Invalid") -> Valid | V82: =IF(OR(N82=0,N82=1),"Valid","Invalid") -> Valid | W82: =IF(OR(L82<$B$23,L82>$B$24),"Outlier","Normal") -> Outlier
A83: USR-100082 | B83: 45724 | C83: Control | D83: South | E83: Mobile | F83: Referral | G83: Free | H83: 1 | I83: 1 | J83: 0 | K83: 0 | L83: 0 | M83: 0 | N83: 0 | P83: 63.8 | Q83: =IF(COUNTIF($A$2:A83,A83)>1,"Duplicate","Unique") -> Unique | R83: =IF(OR(H83=0,H83=1),"Valid","Invalid") -> Valid | S83: =IF(OR(I83=0,I83=1),"Valid","Invalid") -> Valid | T83: =IF(OR(J83=0,J83=1),"Valid","Invalid") -> Valid | U83: =IF(OR(K83=0,K83=1),"Valid","Invalid") -> Valid | V83: =IF(OR(N83=0,N83=1),"Valid","Invalid") -> Valid | W83: =IF(OR(L83<$B$23,L83>$B$24),"Outlier","Normal") -> Outlier
A84: USR-100083 | B84: 45748 | C84: Control | D84: South | E84: Desktop | F84: Email | G84: Free | H84: 0 | I84: 0 | J84: 0 | K84: 0 | L84: 0 | M84: 0 | N84: 0 | P84: 64.7 | Q84: =IF(COUNTIF($A$2:A84,A84)>1,"Duplicate","Unique") -> Unique | R84: =IF(OR(H84=0,H84=1),"Valid","Invalid") -> Valid | S84: =IF(OR(I84=0,I84=1),"Valid","Invalid") -> Valid | T84: =IF(OR(J84=0,J84=1),"Valid","Invalid") -> Valid | U84: =IF(OR(K84=0,K84=1),"Valid","Invalid") -> Valid | V84: =IF(OR(N84=0,N84=1),"Valid","Invalid") -> Valid | W84: =IF(OR(L84<$B$23,L84>$B$24),"Outlier","Normal") -> Outlier
A85: USR-100084 | B85: 45719 | C85: Control | D85: West | E85: Mobile | F85: Social | G85: Basic | H85: 0 | I85: 0 | J85: 0 | K85: 0 | L85: 0 | M85: 0 | N85: 0 | P85: 60.4 | Q85: =IF(COUNTIF($A$2:A85,A85)>1,"Duplicate","Unique") -> Unique | R85: =IF(OR(H85=0,H85=1),"Valid","Invalid") -> Valid | S85: =IF(OR(I85=0,I85=1),"Valid","Invalid") -> Valid | T85: =IF(OR(J85=0,J85=1),"Valid","Invalid") -> Valid | U85: =IF(OR(K85=0,K85=1),"Valid","Invalid") -> Valid | V85: =IF(OR(N85=0,N85=1),"Valid","Invalid") -> Valid | W85: =IF(OR(L85<$B$23,L85>$B$24),"Outlier","Normal") -> Outlier
A86: USR-100085 | B86: 45763 | C86: Control | D86: South | E86: Mobile | F86: Paid Search | G86: Free | H86: 0 | I86: 0 | J86: 0 | K86: 0 | L86: 0 | M86: 0 | N86: 0 | P86: 66.6 | Q86: =IF(COUNTIF($A$2:A86,A86)>1,"Duplicate","Unique") -> Unique | R86: =IF(OR(H86=0,H86=1),"Valid","Invalid") -> Valid | S86: =IF(OR(I86=0,I86=1),"Valid","Invalid") -> Valid | T86: =IF(OR(J86=0,J86=1),"Valid","Invalid") -> Valid | U86: =IF(OR(K86=0,K86=1),"Valid","Invalid") -> Valid | V86: =IF(OR(N86=0,N86=1),"Valid","Invalid") -> Valid | W86: =IF(OR(L86<$B$23,L86>$B$24),"Outlier","Normal") -> Outlier
A87: USR-100086 | B87: 45666 | C87: Control | D87: North | E87: Desktop | F87: Organic | G87: Free | H87: 1 | I87: 0 | J87: 0 | K87: 0 | L87: 0 | M87: 0 | N87: 0 | P87: 50.9 | Q87: =IF(COUNTIF($A$2:A87,A87)>1,"Duplicate","Unique") -> Unique | R87: =IF(OR(H87=0,H87=1),"Valid","Invalid") -> Valid | S87: =IF(OR(I87=0,I87=1),"Valid","Invalid") -> Valid | T87: =IF(OR(J87=0,J87=1),"Valid","Invalid") -> Valid | U87: =IF(OR(K87=0,K87=1),"Valid","Invalid") -> Valid | V87: =IF(OR(N87=0,N87=1),"Valid","Invalid") -> Valid | W87: =IF(OR(L87<$B$23,L87>$B$24),"Outlier","Normal") -> Outlier
A88: USR-100087 | B88: 45679 | C88: Control | D88: West | E88: Desktop | F88: Social | G88: Basic | H88: 0 | I88: 0 | J88: 0 | K88: 0 | L88: 0 | M88: 0 | N88: 0 | P88: 51 | Q88: =IF(COUNTIF($A$2:A88,A88)>1,"Duplicate","Unique") -> Unique | R88: =IF(OR(H88=0,H88=1),"Valid","Invalid") -> Valid | S88: =IF(OR(I88=0,I88=1),"Valid","Invalid") -> Valid | T88: =IF(OR(J88=0,J88=1),"Valid","Invalid") -> Valid | U88: =IF(OR(K88=0,K88=1),"Valid","Invalid") -> Valid | V88: =IF(OR(N88=0,N88=1),"Valid","Invalid") -> Valid | W88: =IF(OR(L88<$B$23,L88>$B$24),"Outlier","Normal") -> Outlier
A89: USR-100088 | B89: 45777 | C89: Control | D89: South | E89: Mobile | F89: Email | G89: Premium | H89: 0 | I89: 0 | J89: 0 | K89: 0 | L89: 0 | M89: 0 | N89: 0 | P89: 65.8 | Q89: =IF(COUNTIF($A$2:A89,A89)>1,"Duplicate","Unique") -> Unique | R89: =IF(OR(H89=0,H89=1),"Valid","Invalid") -> Valid | S89: =IF(OR(I89=0,I89=1),"Valid","Invalid") -> Valid | T89: =IF(OR(J89=0,J89=1),"Valid","Invalid") -> Valid | U89: =IF(OR(K89=0,K89=1),"Valid","Invalid") -> Valid | V89: =IF(OR(N89=0,N89=1),"Valid","Invalid") -> Valid | W89: =IF(OR(L89<$B$23,L89>$B$24),"Outlier","Normal") -> Outlier
A90: USR-100089 | B90: 45772 | C90: Control | D90: North | E90: Mobile | F90: Referral | G90: Basic | H90: 1 | I90: 0 | J90: 0 | K90: 0 | L90: 0 | M90: 0 | N90: 0 | P90: 61.8 | Q90: =IF(COUNTIF($A$2:A90,A90)>1,"Duplicate","Unique") -> Unique | R90: =IF(OR(H90=0,H90=1),"Valid","Invalid") -> Valid | S90: =IF(OR(I90=0,I90=1),"Valid","Invalid") -> Valid | T90: =IF(OR(J90=0,J90=1),"Valid","Invalid") -> Valid | U90: =IF(OR(K90=0,K90=1),"Valid","Invalid") -> Valid | V90: =IF(OR(N90=0,N90=1),"Valid","Invalid") -> Valid | W90: =IF(OR(L90<$B$23,L90>$B$24),"Outlier","Normal") -> Outlier
A91: USR-100090 | B91: 45689 | C91: Control | D91: North | E91: Mobile | F91: Organic | G91: Basic | H91: 1 | I91: 0 | J91: 0 | K91: 0 | L91: 0 | M91: 0 | N91: 0 | P91: 54.5 | Q91: =IF(COUNTIF($A$2:A91,A91)>1,"Duplicate","Unique") -> Unique | R91: =IF(OR(H91=0,H91=1),"Valid","Invalid") -> Valid | S91: =IF(OR(I91=0,I91=1),"Valid","Invalid") -> Valid | T91: =IF(OR(J91=0,J91=1),"Valid","Invalid") -> Valid | U91: =IF(OR(K91=0,K91=1),"Valid","Invalid") -> Valid | V91: =IF(OR(N91=0,N91=1),"Valid","Invalid") -> Valid | W91: =IF(OR(L91<$B$23,L91>$B$24),"Outlier","Normal") -> Outlier
...

Sheet Data_Quality_Check
A1: Total Users | B1: =COUNTA(experiment_data!A:A)-1 -> 1408 | D1: Revenue Outlier Detection
A2: Control Group Users | B2: =COUNTIF(experiment_data!C:C,"Control") -> 693 | D2: Q1 | E2: =_xlfn.QUARTILE.INC(experiment_data!L:L,1) -> 0
A3: Treatment Group Users | B3: =COUNTIF(experiment_data!C:C,"Treatment") -> 715 | D3: Q3 | E3: =_xlfn.QUARTILE.INC(experiment_data!L:L,3) -> 0
A4: Missing User IDs | B4: =COUNTBLANK(experiment_data!A2:A1409) -> 0 | D4: IQR | E4: =E3-E2 -> 0
A5: Missing Region | B5: =COUNTBLANK(experiment_data!D2:D1409) -> 0 | D5: Lower Bound | E5: =E2-(1.5*E4) -> 0
A6: Missing Device Type | B6: =COUNTBLANK(experiment_data!E2:E1409) -> 18 | D6: Upper Bound | E6: =E3+(1.5*E4) -> 0
A7: Missing Traffic Source | B7: =COUNTBLANK(experiment_data!F2:F1409) -> 24
A8: Missing Plan Type | B8: =COUNTBLANK(experiment_data!G2:G1409) -> 0
A9: Missing Revenue | B9: =COUNTBLANK(experiment_data!L2:L1409) -> 0
A10: Missing Days to Convert | B10: =COUNTBLANK(experiment_data!O2:O1409) -> 1336
A11: Missing Engagement Score | B11: =COUNTBLANK(experiment_data!P2:P1409) -> 14
A12: Count duplicates: | B12: =COUNTIF(experiment_data!Q:Q,"Duplicate") -> 8
A13: Trial Count invalid: | B13: =COUNTIF(experiment_data!S:S,"Invalid") -> 0
A14: Onboarding Count invalid: | B14: =COUNTIF(experiment_data!T:T,"Invalid") -> 0
A15: Conversion Count invalid: | B15: =COUNTIF(experiment_data!U:U,"Invalid") -> 0
A16: Refund Count invalid: | B16: =COUNTIF(experiment_data!V:V,"Invalid") -> 0
A17: Revenue Count outliers: | B17: =COUNTIF(experiment_data!W:W,"Outlier") -> 1408

Sheet Summary_Metrics
A1: Metric | C1: Control | E1: Treatment
A2: User Count | C2: =COUNTIF(experiment_data!C:C,"Control") -> 693 | E2: =COUNTIF(experiment_data!C:C,"Treatment") -> 715
A3: Landing Page Visit Rate | C3: =COUNTIFS(experiment_data!C:C,"Control",experiment_data!H:H,1)/COUNTIF(experiment_data!C:C,"Control") -> 0.63636364 | E3: =COUNTIFS(experiment_data!C:C,"Treatment",experiment_data!H:H,1)/COUNTIF(experiment_data!C:C,"Treatment") -> 0.72587413
A4: Trial Start Rate | C4: =COUNTIFS(experiment_data!C:C,"Control",experiment_data!I:I,1)/COUNTIF(experiment_data!C:C,"Control") -> 0.25108225 | E4: =COUNTIFS(experiment_data!C:C,"Treatment",experiment_data!I:I,1)/COUNTIF(experiment_data!C:C,"Treatment") -> 0.29090909
A5: Onboarding Completion Rate | C5: =COUNTIFS(experiment_data!C:C,"Control",experiment_data!J:J,1)/COUNTIF(experiment_data!C:C,"Control") -> 0.15584416 | E5: =COUNTIFS(experiment_data!C:C,"Treatment",experiment_data!J:J,1)/COUNTIF(experiment_data!C:C,"Treatment") -> 0.21258741
A6: Paid Conversion Rate | C6: =COUNTIFS(experiment_data!C:C,"Control",experiment_data!K:K,1)/COUNTIF(experiment_data!C:C,"Control") -> 0.031746032 | E6: =COUNTIFS(experiment_data!C:C,"Treatment",experiment_data!K:K,1)/COUNTIF(experiment_data!C:C,"Treatment") -> 0.06993007
A7: Average Revenue Per User (ARPU) | C7: =SUMIFS(experiment_data!L:L,experiment_data!C:C,"Control")/COUNTIF(experiment_data!C:C,"Control") -> 51.749322 | E7: =SUMIFS(experiment_data!L:L,experiment_data!C:C,"Treatment")/COUNTIF(experiment_data!C:C,"Treatment") -> 53.875119
A8: Average Revenue Per Converted User | C8: =SUMIFS(experiment_data!L:L,experiment_data!C:C,"Control")/COUNTIFS(experiment_data!C:C,"Control",experiment_data!K:K,1) -> 1630.1036 | E8: =SUMIFS(experiment_data!L:L,experiment_data!C:C,"Treatment")/COUNTIFS(experiment_data!C:C,"Treatment",experiment_data!K:K,1) -> 770.4142
A9: Refund Rate | C9: =COUNTIFS(experiment_data!C:C,"Control",experiment_data!N:N,1)/COUNTIF(experiment_data!C:C,"Control") -> 0 | E9: =COUNTIFS(experiment_data!C:C,"Treatment",experiment_data!N:N,1)/COUNTIF(experiment_data!C:C,"Treatment") -> 0.0041958042
A10: Support Ticket Rate | C10: =AVERAGEIFS(experiment_data!M:M,experiment_data!C:C,"Control") -> 0.21933622 | E10: =AVERAGEIFS(experiment_data!M:M,experiment_data!C:C,"Treatment") -> 0.37202797
A11: Average Engagement Score | C11: =AVERAGEIFS(experiment_data!P:P,experiment_data!C:C,"Control") -> 57.026201 | E11: =AVERAGEIFS(experiment_data!P:P,experiment_data!C:C,"Treatment") -> 62.931966
A12: Average Days to Convert | C12: =AVERAGEIFS(experiment_data!O:O,experiment_data!C:C,"Control",experiment_data!K:K,1) -> 8.8636364 | E12: =AVERAGEIFS(experiment_data!O:O,experiment_data!C:C,"Treatment",experiment_data!K:K,1) -> 6.4

Sheet Segment_Analysis
A1: Control Conversions | D1: Control Conversion Rate
A2: =COUNTIFS(experiment_data!C:C,"Control",experiment_data!K:K,1) -> 22 | D2: =A2/A6 -> 0.031746032
A3: Treatment Conversions
A4: =COUNTIFS(experiment_data!C:C,"Treatment",experiment_data!K:K,1) -> 50 | D4: Treatment Conversion Rate
A5: Control Users | D5: =A4/A8 -> 0.06993007
A6: =COUNTIF(experiment_data!C:C,"Control") -> 693
A7: Treatment Users | D7: Pooled Conversion Rate
A8: =COUNTIF(experiment_data!C:C,"Treatment") -> 715 | D8: =(A2+A4)/(A6+A8) -> 0.051136364
D10: Standard Error
D11: =SQRT(D8*(1-D8)*((1/A6)+(1/A8))) -> 0.011742174
D13: Z Score
D15: =(D5-D2)/D11 -> 3.2518713
D16: P Value
D17: =1-_xlfn.NORM.S.DIST(D15,TRUE) -> 0.00057323969
D19: Decision
D20: =IF(D17<0.05,"Reject Null Hypothesis","Fail to Reject Null Hypothesis") -> Reject Null Hypothesis

Sheet Region Conversion Analysis
A3: Average of converted_to_paid | B3: Column Labels
A4: Row Labels | B4: Control | C4: Treatment | D4: Grand Total
A5: East | B5: 0.025316456 | C5: 0.063953488 | D5: 0.045454545
A6: North | B6: 0.034482759 | C6: 0.088888889 | D6: 0.060052219
A7: South | B7: 0.032608696 | C7: 0.076086957 | D7: 0.054347826
A8: West | B8: 0.033783784 | C8: 0.05027933 | D8: 0.042813456
A9: Grand Total | B9: 0.031746032 | C9: 0.06993007 | D9: 0.051136364

Sheet Device Type Conversion Analysis
A3: Average of converted_to_paid | B3: Column Labels
A4: Row Labels | B4: Control | C4: Treatment | D4: Grand Total
A5: Desktop | B5: 0.045 | C5: 0.065420561 | D5: 0.055555556
A6: Mobile | B6: 0.025700935 | C6: 0.073394495 | D6: 0.049768519
A7: Tablet | B7: 0.017857143 | C7: 0.071428571 | D7: 0.044642857
A8: (blank) | B8: 0.11111111 | C8: 0 | D8: 0.055555556
A9: Grand Total | B9: 0.031746032 | C9: 0.06993007 | D9: 0.051136364

Sheet Traffic Source Conversion Analy
A3: Average of converted_to_paid | B3: Column Labels
A4: Row Labels | B4: Control | C4: Treatment | D4: Grand Total
A5: Email | B5: 0.027027027 | C5: 0.071428571 | D5: 0.046153846
A6: Organic | B6: 0.020325203 | C6: 0.062240664 | D6: 0.041067762
A7: Paid Search | B7: 0.012820513 | C7: 0.0625 | D7: 0.039156627
A8: Referral | B8: 0.024691358 | C8: 0.10989011 | D8: 0.069767442
A9: Social | B9: 0.076923077 | C9: 0.060150376 | D9: 0.068441065
A10: (blank) | B10: 0.16666667 | C10: 0.11111111 | D10: 0.125
A11: Grand Total | B11: 0.031746032 | C11: 0.06993007 | D11: 0.051136364

Sheet Plan Type Conversion Analysis
A3: Average of converted_to_paid | B3: Column Labels
A4: Row Labels | B4: Control | C4: Treatment | D4: Grand Total
A5: Basic | B5: 0.035874439 | C5: 0.038297872 | D5: 0.037117904
A6: Free | B6: 0.030470914 | C6: 0.092391304 | D6: 0.061728395
A7: Premium | B7: 0.027522936 | C7: 0.0625 | D7: 0.045248869
A8: Grand Total | B8: 0.031746032 | C8: 0.06993007 | D8: 0.051136364

Sheet business_context
A1: Item | B1: Description
A2: Business context | B2: A subscription product tested a new onboarding and activation campaign against the existing experience.
A3: Control | B3: Existing onboarding experience.
A4: Treatment | B4: New campaign experience.
A5: Primary decision | B5: Decide whether to launch, reject, continue testing, or launch only for selected segments.
A6: visited_landing_page | B6: 1 if the user visited the landing page after signup; otherwise 0.
A7: started_trial | B7: 1 if the user started a trial; otherwise 0.
A8: completed_onboarding | B8: 1 if the user completed onboarding; otherwise 0.
A9: converted_to_paid | B9: 1 if the user became a paid customer; otherwise 0.
A10: revenue_30d | B10: Revenue generated within 30 days of signup.
A11: support_tickets_30d | B11: Number of support tickets raised within 30 days.
A12: refund_requested | B12: 1 if the user requested a refund; otherwise 0.
... A14: Guardrail caution | B14: A better conversion rate may still be risky if refunds, support tickets, or low-quality revenue increase.
